Traceback (most recent call last):
  File "/Library/Frameworks/Python.framework/Versions/3.12/lib/python3.12/site-packages/jupyter_cache/executors/utils.py", line 58, in single_nb_execution
    executenb(
  File "/Library/Frameworks/Python.framework/Versions/3.12/lib/python3.12/site-packages/nbclient/client.py", line 1314, in execute
    return NotebookClient(nb=nb, resources=resources, km=km, **kwargs).execute()
           ^^^^^^^^^^^^^^^^^^^^^^^^^^^^^^^^^^^^^^^^^^^^^^^^^^^^^^^^^^^^^^^^^^^^^
  File "/Users/gussie/Library/Python/3.12/lib/python/site-packages/jupyter_core/utils/__init__.py", line 165, in wrapped
    return loop.run_until_complete(inner)
           ^^^^^^^^^^^^^^^^^^^^^^^^^^^^^^
  File "/Library/Frameworks/Python.framework/Versions/3.12/lib/python3.12/asyncio/base_events.py", line 684, in run_until_complete
    return future.result()
           ^^^^^^^^^^^^^^^
  File "/Library/Frameworks/Python.framework/Versions/3.12/lib/python3.12/site-packages/nbclient/client.py", line 709, in async_execute
    await self.async_execute_cell(
  File "/Library/Frameworks/Python.framework/Versions/3.12/lib/python3.12/site-packages/nbclient/client.py", line 1062, in async_execute_cell
    await self._check_raise_for_error(cell, cell_index, exec_reply)
  File "/Library/Frameworks/Python.framework/Versions/3.12/lib/python3.12/site-packages/nbclient/client.py", line 918, in _check_raise_for_error
    raise CellExecutionError.from_cell_and_msg(cell, exec_reply_content)
nbclient.exceptions.CellExecutionError: An error occurred while executing the following cell:
------------------
import pandas as pd
import plotly.express as px
import plotly.io as pio

pio.templates.default = "plotly_white"

import statsmodels.api as sm

# Data import
survey_cols = [
    "general_trust",
    "GPS_trust",
    "general_morality",
    "MFQ_genmorality",
    "civic_cooperation",
    "GPS_posrecip",
    "GPS_altruism",
    "stranger1",
]

cat_cols = [
    "country",
    "response",
    "male",
    "above40",
    "computer",
    "coworkers",
    "other_bystanders",
    "institution",
    "cond",
    "security_cam",
    "security_guard",
    "local_recipient",
    "no_english",
    "understood_situation",
]

sc_cols = [
    "log_gdp",
    "log_tfp",
    "gee",
    "letter_grading",
]

# Import Tannenbaum data
df = pd.read_csv(
    "../data/tannenbaum_data.csv",
    dtype={col: "category" for col in cat_cols},
)

# Import PISA data
pisa = pd.read_csv("../data/pisa_data.csv").rename(columns={"mean_score": "pisa_score"})
df = df.merge(pisa, how="left", on="country")

# Columns we want to see correlations for.
cols_for_country_avg_corr = ["response", "pisa_score"] + survey_cols

df_corr = df.copy().astype({"response": int})

# Calculate country averages for these measures
country_avg_data = df_corr.groupby("country")[cols_for_country_avg_corr].mean()

# Compute the correlation matrix
comprehensive_corr_matrix = country_avg_data.corr()

# Show correlations of interest
comprehensive_corr_matrix.columns = pd.MultiIndex.from_product(
    [["Correlation (r)"], comprehensive_corr_matrix.columns]
)
comprehensive_corr_matrix.iloc[:2, 2:]
------------------


[0;31m---------------------------------------------------------------------------[0m
[0;31mModuleNotFoundError[0m                       Traceback (most recent call last)
Cell [0;32mIn[1], line 2[0m
[1;32m      1[0m [38;5;28;01mimport[39;00m [38;5;21;01mpandas[39;00m [38;5;28;01mas[39;00m [38;5;21;01mpd[39;00m
[0;32m----> 2[0m [38;5;28;01mimport[39;00m [38;5;21;01mplotly[39;00m[38;5;21;01m.[39;00m[38;5;21;01mexpress[39;00m [38;5;28;01mas[39;00m [38;5;21;01mpx[39;00m
[1;32m      3[0m [38;5;28;01mimport[39;00m [38;5;21;01mplotly[39;00m[38;5;21;01m.[39;00m[38;5;21;01mio[39;00m [38;5;28;01mas[39;00m [38;5;21;01mpio[39;00m
[1;32m      5[0m pio[38;5;241m.[39mtemplates[38;5;241m.[39mdefault [38;5;241m=[39m [38;5;124m"[39m[38;5;124mplotly_white[39m[38;5;124m"[39m

[0;31mModuleNotFoundError[0m: No module named 'plotly'

